Workbook

Sheet Prospects
A1: City | B1: Business Name | C1: Phone | D1: Has Website | E1: Website URL | F1: Website Quality | G1: Google Rating | H1: Review Count | I1: Flag | J1: Owner Name | K1: Notes | L1: Source | M1: Date Found | N1: Contacted (Y/N) | O1: Contact Date | P1: Response / Outcome
A2: Arlington | B2: Service Max Heating & Air Conditioning, LLC | C2: (360) 333-5904 | D2: Yes (broken) | E2: servicemaxheating.com | F2: Broken / not loading | G2: 4.6 | H2: 46 | I2: Warm | J2: Mike Raether | K2: Domain exists but site failed to load on repeated visits (error page) - effectively no working web presence. Family-owned since 2012 | L2: Google Maps; WebSearch; direct site visit | M2: 2026-07-02 | N2: Y | O2: 2026-07-14 | P2: Went to voicemail — call again (owner voicemail = good sign) | July 14 — 2nd voicemail left. Said: second time calling, know you're busy, have something to let customers book when they can't reach you. Left callback # 425-309-9782.
A3: Arlington | B3: A-Service: Heating, Cooling & Appliance Repair Arlington | C3: (360) 859-8185 | D3: No | E3: N/A | F3: N/A | G3: 5 | H3: 169 | I3: Hot | J3: 3rd-gen technician (name not confirmed) | K3: No dedicated business website found. Top search result for the name (services-wa.com) is an unrelated Eastern WA business with a different phone number and review count. Relies on Google + Nextdoor listing only | L3: Google Maps; WebSearch; Nextdoor | M3: 2026-07-02 | N3: Y | O3: 2026-07-14 | P3: Called — AI answering system, no human reached. Call again. | July 14 — AI agent again, no human reached. Try early morning or after 5pm.
A4: Arlington | B4: AeroCool Heating and Air Conditioning | C4: (425) 405-4876 | D4: Yes | E4: aerocoolservices.com | F4: Amateurish / DIY template | G4: 5 | H4: 43 | I4: Warm | J4: Carson Brender | K4: Generic template-builder site, awkward copy ("Speak With a Licensed Technician Licensed Now"), thin content, stock contact form | L4: Google Maps; WebSearch; direct site visit | M4: 2026-07-02 | N4: Y | O4: 2026-07-14 | P4: No answer — call again. Note: site has HouseCall Pro booking widget already active. | July 14 — voice agent again. Left inquiry about their HouseCall Pro booking feature. Told them best callback time is before 11am. | July 14 — spoke to Jeremy (staff). Got Rusty's personal cell (transcript garbled — Jose has it). Best time to call: after 12pm today.
A5: Arlington | B5: Anderson Mechanical Heating & Cooling INC. | C5: (425) 422-0160 | D5: No | E5: N/A | F5: N/A | G5: 4.9 | H5: 14 | I5: Watch | J5: Jesse Anderson (registered agent) | K5: No website found. Only 14 reviews so it doesn't yet clear the 30+ review bar - worth rechecking as it grows | L5: Google Maps; WebSearch | M5: 2026-07-02 | N5: N
A6: Arlington | B6: Frog HVAC LLC | C6: (425) 359-7988 | D6: Yes | E6: froghvac.com | F6: Warm - grammatical error in hero headline ("Based Of Arlington" instead of "Based In"), generic stock photo of unrelated modern architectural interior (not their own trucks/team), garish rainbow frog mascot clashing with green header/orange CTA scheme | G6: 4.6 | H6: 28 | I6: Warm | K6: 28 reviews clears the new 25+ bar. Site technically exists but actively hurts them - stock photography instead of real work, plus a copy error on the hero headline. Good "here's specifically what's broken" pitch. | L6: Google Maps | M6: 2026-07-02 | N6: N
A7: Marysville | B7: Montanos Heating & Cooling Services | C7: (425) 314-1814 | D7: Yes | E7: montanosheating.com | F7: Outdated / amateurish | G7: 5 | H7: 54 | I7: Warm | J7: Joel (last name not confirmed) | K7: Generic dark template, mismatched personal-vehicle stock photo, business email is a @gmail.com address, overlapping lead-gen popup blocks page content | L7: Google Maps; WebSearch; direct site visit | M7: 2026-07-02 | N7: Y | O7: 2026-07-14 | P7: July 14 — no answer, no voicemail.
A8: Marysville | B8: Kodiak Heating and Cooling | C8: (425) 883-4871 | D8: Yes | E8: kodiakheatingandcooling.com | F8: Dated / generic | G8: 5 | H8: 91 | I8: Warm | J8: Thomas Hager & Steven Hyde | K8: Uses generic stock family photo (not their own team or trucks), dated template layout | L8: Google Maps; WebSearch; direct site visit | M8: 2026-07-02 | N8: Y | O8: 2026-07-14 | P8: July 14 — Nicole (staff) answered. Thomas/Steven not in. Website was just revamped — skip website angle. Actually Washington Water Heaters (tankless specialist). Got Tom email: tanklesstom@gmail.com. Send booking pitch email.
A9: Stanwood | B9: Cool Heat 365 LLC | C9: (425) 740-4212 | D9: Yes | E9: coolheat365.com | F9: Amateurish / outdated | G9: 4.8 | H9: 367 | I9: Warm | J9: Rusty (last name not confirmed) | K9: Cartoon-style flame mascot logo, business email is a @yahoo.com address, broken icon placeholders next to contact info in header | L9: Google Maps; WebSearch; direct site visit | M9: 2026-07-02 | N9: Y | O9: 2026-07-14 | P9: July 14 — spoke to Jeremy (staff). Got Rusty's personal cell (transcript garbled — Jose has it). Best time to call: after 12pm today.
A10: Mount Vernon | B10: Handy's Heating | C10: (360) 428-0969 | D10: Yes | E10: handysheating.com | F10: Outdated | G10: 4.6 | H10: 260 | I10: Warm | K10: Dated embossed-text logo, homepage banner still promoting a stale seasonal ("holidays") tune-up offer, generic stock house photo | L10: Google Maps; WebSearch; direct site visit | M10: 2026-07-02 | N10: N
A11: Mount Vernon | B11: Nordic Temperature Control | C11: (360) 873-8163 | D11: Yes | E11: nordictempcontrol.com | F11: Cluttered / dated | G11: 4.9 | H11: 130 | I11: Warm | K11: Aggressive SMS sign-up popup on load, multiple stacked widgets (chat bubble, HomeAdvisor badge, cookie banner) creating cluttered UX | L11: Google Maps; WebSearch; direct site visit | M11: 2026-07-02 | N11: Y | O11: 2026-07-14 | P11: July 14 — screener answered, directed to email. Got contact email (transcript garbled — likely contact@nordictemperaturecontrol.com — verify). Send booking pitch email.
A12: Mount Vernon (Burlington) | B12: Alpine Heating and Cooling | C12: (360) 755-5146 | D12: Yes | E12: alpineheat.com | F12: Dated | G12: 4.7 | H12: 82 | I12: Warm | K12: Serviceable but dated site - lacks inline lead capture form and a modern visual refresh | L12: Google Maps; WebSearch | M12: 2026-07-02 | N12: N
A13: Everett | B13: AirPros Energy Heating and Cooling | C13: (425) 600-7540 | D13: Yes | E13: airprosenergy.com | F13: Amateurish | G13: 5 | H13: 139 | I13: Warm | J13: Richie & Mark (co-founders, 2007) | K13: No logo/branding in header, plain text-heavy layout, grammatical typo in hero copy ("take control your home comfort") | Has online booking feature on website already — warm lead, skip the booking education, go straight to website quality angle. | L13: Google Maps; WebSearch; direct site visit | M13: 2026-07-02 | N13: N | O13: 2026-07-14 | P13: July 14 — no answer, no voicemail. | July 14 — receptionist picked up (owner unavailable). Has online booking but SET TIMES only, not live availability. Got email: info@airprosenergy.com. Send follow-up email today.
A14: Everett | B14: Top Quality Home Service | C14: (425) 365-5589 | D14: No | E14: N/A | F14: N/A | G14: 5 | H14: 32 | I14: Hot | J14: Cody (last name not confirmed) | K14: No dedicated business website found despite a "Website" link on the Google listing; searches turn up only directory/aggregator pages, not an owned site | L14: Google Maps; WebSearch | M14: 2026-07-02 | N14: Y | O14: 2026-07-13 | P14: No answer — call again | Called back — panicked, posed as customer needing AC repair, bailed. Call back tomorrow, open by owning it.
A15: Everett | B15: Climate Pro LLC | C15: (425) 787-5804 | D15: Yes | E15: climatepronw.com | F15: Dated | G15: 4.6 | H15: 38 | I15: Warm | K15: Generic stock family photo, cluttered dated template, UI text-overlap glitch in hero banner | L15: Google Maps; WebSearch; direct site visit | M15: 2026-07-02 | N15: N
A16: Lake Stevens | B16: Arctic Heat LLC | C16: (360) 540-1920 | D16: No | E16: N/A | F16: N/A | G16: 5 | H16: 75 | I16: Hot | J16: Sergey & Natalia Nikolin | K16: No dedicated website found; only directory/social listings (Facebook, Yelp, BBB, Networx) turn up | L16: Google Maps; WebSearch | M16: 2026-07-02 | N16: Y | O16: 2026-07-08 | P16: Called — business closed. Sergey now works for different company. Dead lead.
A17: Lake Stevens | B17: Puget Heating Company | C17: (425) 334-4111 | D17: Yes | E17: pugetheating.com | F17: Very outdated | G17: 4.8 | H17: 37 | I17: Warm | K17: Established 1974; cloudy-sky gradient background, cartoon mechanic mascot, clip-art scalloped borders around product photos - classic mid-2000s design | L17: Google Maps; WebSearch; direct site visit | M17: 2026-07-02 | N17: N
A18: Lake Stevens | B18: Elevated Mechanical LLC | C18: (425) 530-7192 | D18: Yes | E18: elevatedmechanicalnw.com | F18: Amateurish / thin | G18: 5 | H18: 34 | I18: Warm | K18: Bare no-code template site - just a centered logo on a blank page, no hero content or CTA, business email is a @gmail.com address | L18: Google Maps; WebSearch; direct site visit | M18: 2026-07-02 | N18: N
A19: Snohomish | B19: McFarland Heating & Air | C19: (360) 568-4205 | D19: Yes | E19: mcfarlandhvac.com | F19: Broken / technical issues | G19: 5 | H19: 46 | I19: Hot | J19: Howard, Andy & Zack (family owners) | K19: Page title tag shows raw unescaped HTML code ("McFarland Heating & Air<br />360-568-4205") - a broken/badly coded site | L19: Google Maps; WebSearch | M19: 2026-07-02 | N19: Y | O19: 2026-07-14 | P19: VERBAL YES — Zach (co-owner) picked up. Said no twice, Jose pivoted with free case study offer. Zach: I dig that, send me a mock-up. Gave personal cell. Bonded over AI. Text demo link NOW.
A20: Snohomish | B20: Pilchuck Heating | C20: (425) 585-0659 | D20: Yes | E20: pilchuckheating.com | F20: Broken / buggy | G20: 4.3 | H20: 32 | I20: Warm | K20: Navigation bar renders duplicated and stacked on page load, large broken empty sections - clear front-end bugs | L20: Google Maps; WebSearch; direct site visit | M20: 2026-07-02 | N20: N
A21: Snohomish | B21: Snohomish Furnace & Air Conditioning | C21: (425) 610-6635 | D21: Yes | E21: snohomishfurnace.com | F21: Cluttered / stale | G21: 4.7 | H21: 168 | I21: Do Not Call | K21: Intrusive popup blocks content on load, homepage still promoting a stale "Spring Service" offer in July | L21: Google Maps; WebSearch; direct site visit | M21: 2026-07-02 | N21: Y | O21: 2026-07-14 | P21: July 14 — owner picked up. Spring sale opener landed but GoDaddy follow-up triggered ARE YOU SELLING ME SOMETHING. Hung up. Not interested.
A22: Lynnwood | B22: Lynnwood Heating LLC | C22: (206) 741-6980 | D22: Yes | E22: hvaclynnwood.com | F22: Unpolished | G22: 4.8 | H22: 155 | I22: Warm | K22: Large broken-looking blank white gap at top of homepage before content loads; business email is a @gmail.com address | L22: Google Maps; WebSearch; direct site visit | M22: 2026-07-02 | N22: N
A23: Monroe | B23: Genesis Heating, Cooling & Refrigeration | C23: (425) 261-9095 | D23: Yes | E23: genesishvacr.com | F23: Broken / technical issues | G23: 4.8 | H23: 73 | I23: Warm | K23: Broken icon font (tofu boxes) throughout nav/header, large blank empty section below nav where hero content should render | L23: Google Maps; WebSearch; direct site visit | M23: 2026-07-02 | N23: N
A24: Oak Harbor | B24: A&R HVAC LLC | C24: (360) 499-1829 | D24: Yes (not real site) | E24: anrhvac.com | F24: No real site - link-in-bio page | G24: 5 | H24: 67 | I24: Skip | K24: Domain just redirects to a bare "link in bio" style landing page (literal page title), not an actual business website. Business email is a @gmail.com address | L24: Google Maps; WebSearch; direct site visit | M24: 2026-07-02 | N24: N | P24: July 14 — already using Jobber for booking. Skip.
A25: Sedro-Woolley | B25: Right Way Plumbing & Heating | C25: (360) 855-2665 | D25: Yes | E25: rightwayplumb-heat.com | F25: Dated | G25: 4.2 | H25: 33 | I25: Warm | K25: Massively keyword-stuffed page title (SEO spam from an older era), western-saloon style drop-shadow serif font for headings, generic warehouse stock photo | L25: Google Maps; WebSearch; direct site visit | M25: 2026-07-02 | N25: N
A26: Sedro-Woolley | B26: Taxdahl Heating & Air Conditioning | C26: (360) 708-4675 | D26: Yes | E26: taxdahlheating.com | F26: Dated | G26: 4.9 | H26: 31 | I26: Warm | K26: Basic, outdated site design with no lead capture form or modern visual refresh | L26: Google Maps; WebSearch | M26: 2026-07-02 | N26: N
A27: Ferndale | B27: A Plus Heating and Air Conditioning | C27: (564) 209-4966 | D27: No | E27: facebook.com (no dedicated site) | F27: N/A | G27: 5 | H27: 33 | I27: Hot | J27: Vlad | K27: No real website - Maps/search only surfaces a Facebook page as their web presence. Owner Vlad confirmed via multiple reviews ("Vlad and his son were extremely professional...", "Vlad replaced our furnace..."). | L27: Google Maps; WebSearch | M27: 2026-07-02 | N27: Y | O27: 2026-07-14 | P27: Called x2 — no answer both times. Call again. | July 14 — no answer, no voicemail. 3rd attempt. Try before 8am.
A28: Port Orchard | B28: Simons Heating Cooling & Appliance Repair | C28: (253) 649-9922 | D28: Yes | E28: simonshvacrepair.com | F28: Warm - broken/thin site (huge blank white gaps below nav, testimonials section never loads), generic unbranded pill-button nav, no real hero/logo imagery, cheap "by Smartarget" 3rd-party widget badge, gmail contact | G28: 5 | H28: 37 | I28: Warm | K28: 3+ red flag signals: broken layout, no branding, cheap widget, gmail email (SIMONSHEATINGCOOLINGAPPLIANCE@GMAIL.COM) | L28: Google Maps; WebSearch | M28: 2026-07-02 | N28: N
A29: Ferndale | B29: Whatcom Heating and Air Conditioning LLC | C29: (360) 389-7583 | D29: Yes | E29: whatcomhvac.com | F29: Warm - severely underbuilt site: plain text-only header (no logo/branding), massive blank gray space below nav with zero hero content/CTA/headline, only a small Facebook icon link | G29: 5 | H29: 31 | I29: Warm | K29: Also serves Lynden - same business. Site is essentially non-functional as a marketing/lead-gen tool despite technically "having a website". | L29: Google Maps; WebSearch | M29: 2026-07-02 | N29: N
A30: Port Orchard | B30: Air Anderson Inc. | C30: (360) 674-7125 | D30: Yes | F30: Not assessed | G30: 4.2 | H30: 15 | I30: Watch | K30: Below 25+ review threshold - recheck later | L30: Google Maps | M30: 2026-07-02 | N30: N
A31: Port Orchard | B31: A & M Heating | C31: (360) 895-8580 | D31: No | E31: N/A | F31: N/A | G31: 4.5 | H31: 15 | I31: Watch | K31: No website shown on Maps; below 25+ review threshold - recheck later | L31: Google Maps | M31: 2026-07-02 | N31: N
A32: Poulsbo | B32: YJK Dryer vent & Air Duct Cleaning Services | C32: (360) 276-5825 | D32: No | E32: N/A | F32: N/A | G32: 4.6 | H32: 20 | I32: Watch | K32: Below 25+ review threshold; narrower duct-cleaning scope rather than full HVAC - recheck later | L32: Google Maps | M32: 2026-07-02 | N32: N
A33: Silverdale | B33: Brooks Comfort Zone LLC | C33: (360) 643-0539 | D33: Yes | F33: Not assessed | G33: 4.1 | H33: 23 | I33: Watch | K33: Below 25+ review threshold - recheck later | L33: Google Maps | M33: 2026-07-02 | N33: N
A34: Silverdale | B34: Mayda & Sons Mechanical | C34: (360) 692-9003 | D34: Yes | F34: Not assessed | G34: 4.7 | H34: 15 | I34: Watch | K34: Below 25+ review threshold - recheck later | L34: Google Maps | M34: 2026-07-02 | N34: N
A35: Ferndale | B35: Andy Refrigeration | C35: (360) 820-9801 | D35: Yes | F35: Not assessed | G35: 4.1 | H35: 12 | I35: Watch | K35: Below 25+ review threshold - recheck later | L35: Google Maps | M35: 2026-07-02 | N35: N
A36: Ferndale | B36: Mumm's LLC Heating & A/C contractor | C36: (360) 201-4822 | D36: Yes | F36: Not assessed | G36: 4.8 | H36: 12 | I36: Watch | K36: Below 25+ review threshold - recheck later | L36: Google Maps | M36: 2026-07-02 | N36: N
A37: Lynden | B37: Solera Hurley HVAC Contractor Lynden | C37: (253) 367-2447 | D37: No | E37: N/A | F37: N/A | G37: 5 | H37: 10 | I37: Watch | K37: No website shown on Maps; below 25+ review threshold. Name suggests possible franchise/rebrand - worth rechecking as it grows | L37: Google Maps | M37: 2026-07-02 | N37: N
A38: Lynden | B38: Reliance Indoor Air Quality Heating & Air Conditioning | C38: (360) 410-9159 | D38: Yes | F38: Not assessed | G38: 4.8 | H38: 16 | I38: Watch | K38: Below 25+ review threshold - recheck later | L38: Google Maps | M38: 2026-07-02 | N38: Y | O38: 2026-07-09 | P38: VERBAL YES — free case study. Justin on rooftop, said text him the link. Follow up with text NOW.
A39: Yelm | B39: Manus Mechanical | C39: (253) 248-5925 | D39: No | E39: N/A | F39: No website - Maps shows "Add website" prompt | G39: 5 | H39: 26 | I39: Hot | J39: Alex Manus | K39: No website at all, confirmed via Maps "Add missing information" prompt. Owner name confirmed via reviews. | L39: Google Maps | M39: 2026-07-02 | N39: Y | O39: 2026-07-09 | P39: Called x2 + callback — not interested. Do not call again.
A40: Yelm | B40: Ed's Heating and Cooling LLC | C40: (253) 753-8177 | D40: Yes (dead) | E40: edsheatingandcoolingwa.com | F40: Domain dead - "Domain not found"/privacy error on https and http | G40: 5 | H40: 231 | I40: Hot | K40: Best find of Round 6 - 231 reviews, 5.0 stars, but domain completely dead on both https and http. | L40: Google Maps | M40: 2026-07-02 | N40: Y | O40: 2026-07-14 | P40: Called x2 — voicemail both times. Left voicemail on 2nd attempt. Call again Day 5. | July 14 — 3rd attempt, voicemail left. Said: tried a couple times, have a system to capture missed calls so they don't lose prospects. Left callback #.
...

Sheet Summary
A1: Metric | B1: Count
A2: Total businesses logged | B2: =COUNTA(Prospects!B2:B1000)+COUNTA('Skipped (Reference)'!B2:B1000)
A3: Hot (no website, 4+ stars, 25+ reviews) | B3: =COUNTIF(Prospects!I2:I1000,"Hot")
A4: Warm (bad/broken website, 4+ stars, 25+ reviews) | B4: =COUNTIF(Prospects!I2:I1000,"Warm")
A5: Watch (close but under review threshold) | B5: =COUNTIF(Prospects!I2:I1000,"Watch")
A6: Skip (moved to reference tab) | B6: =COUNTA('Skipped (Reference)'!B2:B1000)
A7: Arlington businesses logged | B7: =COUNTIF(Prospects!A2:A1000,"Arlington")+COUNTIF('Skipped (Reference)'!A2:A1000,"Arlington")
A8: Marysville businesses logged | B8: =COUNTIF(Prospects!A2:A1000,"Marysville")+COUNTIF('Skipped (Reference)'!A2:A1000,"Marysville")
A9: Stanwood businesses logged | B9: =COUNTIF(Prospects!A2:A1000,"Stanwood")+COUNTIF('Skipped (Reference)'!A2:A1000,"Stanwood")
A10: Mount Vernon businesses logged | B10: =COUNTIF(Prospects!A2:A1000,"Mount Vernon")+COUNTIF('Skipped (Reference)'!A2:A1000,"Mount Vernon")
A11: Everett businesses logged | B11: =COUNTIF(Prospects!A2:A1000,"Everett")+COUNTIF('Skipped (Reference)'!A2:A1000,"Everett")
A12: Lake Stevens businesses logged | B12: =COUNTIF(Prospects!A2:A1000,"Lake Stevens")+COUNTIF('Skipped (Reference)'!A2:A1000,"Lake Stevens")
A13: Snohomish businesses logged | B13: =COUNTIF(Prospects!A2:A1000,"Snohomish")+COUNTIF('Skipped (Reference)'!A2:A1000,"Snohomish")
A14: Lynnwood businesses logged | B14: =COUNTIF(Prospects!A2:A1000,"Lynnwood")+COUNTIF('Skipped (Reference)'!A2:A1000,"Lynnwood")
A15: Edmonds businesses logged | B15: =COUNTIF(Prospects!A2:A1000,"Edmonds")+COUNTIF('Skipped (Reference)'!A2:A1000,"Edmonds")
A16: Monroe businesses logged | B16: =COUNTIF(Prospects!A2:A1000,"Monroe")+COUNTIF('Skipped (Reference)'!A2:A1000,"Monroe")
A17: Sedro-Woolley businesses logged | B17: =COUNTIF(Prospects!A2:A1000,"Sedro-Woolley")+COUNTIF('Skipped (Reference)'!A2:A1000,"Sedro-Woolley")
A18: Oak Harbor businesses logged | B18: =COUNTIF(Prospects!A2:A1000,"Oak Harbor")+COUNTIF('Skipped (Reference)'!A2:A1000,"Oak Harbor")
A19: Sultan businesses logged | B19: =COUNTIF(Prospects!A2:A1000,"Sultan")+COUNTIF('Skipped (Reference)'!A2:A1000,"Sultan")
A20: Camano Island businesses logged | B20: =COUNTIF(Prospects!A2:A1000,"Camano Island")+COUNTIF('Skipped (Reference)'!A2:A1000,"Camano Island")
A21: Anacortes businesses logged | B21: =COUNTIF(Prospects!A2:A1000,"Anacortes")+COUNTIF('Skipped (Reference)'!A2:A1000,"Anacortes")
A22: Mukilteo businesses logged | B22: =COUNTIF(Prospects!A2:A1000,"Mukilteo")+COUNTIF('Skipped (Reference)'!A2:A1000,"Mukilteo")
A23: Bellingham businesses logged | B23: =COUNTIF(Prospects!A2:A1000,"Bellingham")+COUNTIF('Skipped (Reference)'!A2:A1000,"Bellingham")
A24: Bremerton businesses logged | B24: =COUNTIF(Prospects!A2:A1000,"Bremerton")+COUNTIF('Skipped (Reference)'!A2:A1000,"Bremerton")
A25: Port Orchard businesses logged | B25: =COUNTIF(Prospects!A2:A1000,"Port Orchard")+COUNTIF('Skipped (Reference)'!A2:A1000,"Port Orchard")
A26: Poulsbo businesses logged | B26: =COUNTIF(Prospects!A2:A1000,"Poulsbo")+COUNTIF('Skipped (Reference)'!A2:A1000,"Poulsbo")
A27: Silverdale businesses logged | B27: =COUNTIF(Prospects!A2:A1000,"Silverdale")+COUNTIF('Skipped (Reference)'!A2:A1000,"Silverdale")
A28: Ferndale businesses logged | B28: =COUNTIF(Prospects!A2:A1000,"Ferndale")+COUNTIF('Skipped (Reference)'!A2:A1000,"Ferndale")
A29: Lynden businesses logged | B29: =COUNTIF(Prospects!A2:A1000,"Lynden")+COUNTIF('Skipped (Reference)'!A2:A1000,"Lynden")
A30: Blaine businesses logged | B30: =COUNTIF(Prospects!A2:A1000,"Blaine")+COUNTIF('Skipped (Reference)'!A2:A1000,"Blaine")
A31: Puyallup businesses logged | B31: =COUNTIF(Prospects!A2:A1000,"Puyallup")+COUNTIF('Skipped (Reference)'!A2:A1000,"Puyallup")
A32: Yelm businesses logged | B32: =COUNTIF(Prospects!A2:A1000,"Yelm")+COUNTIF('Skipped (Reference)'!A2:A1000,"Yelm")
A33: Orting businesses logged | B33: =COUNTIF(Prospects!A2:A1000,"Orting")+COUNTIF('Skipped (Reference)'!A2:A1000,"Orting")
A34: Eatonville businesses logged | B34: =COUNTIF(Prospects!A2:A1000,"Eatonville")+COUNTIF('Skipped (Reference)'!A2:A1000,"Eatonville")
A35: Buckley businesses logged | B35: =COUNTIF(Prospects!A2:A1000,"Buckley")+COUNTIF('Skipped (Reference)'!A2:A1000,"Buckley")
A36: Port Angeles businesses logged | B36: =COUNTIF(Prospects!A2:A1000,"Port Angeles")+COUNTIF('Skipped (Reference)'!A2:A1000,"Port Angeles")
A37: Sequim businesses logged | B37: =COUNTIF(Prospects!A2:A1000,"Sequim")+COUNTIF('Skipped (Reference)'!A2:A1000,"Sequim")
A38: Port Townsend businesses logged | B38: =COUNTIF(Prospects!A2:A1000,"Port Townsend")+COUNTIF('Skipped (Reference)'!A2:A1000,"Port Townsend")
A39: Everson businesses logged | B39: =COUNTIF(Prospects!A2:A1000,"Everson")+COUNTIF('Skipped (Reference)'!A2:A1000,"Everson")
A40: Nooksack businesses logged | B40: =COUNTIF(Prospects!A2:A1000,"Nooksack")+COUNTIF('Skipped (Reference)'!A2:A1000,"Nooksack")
...

Sheet Skipped (Reference)
A1: City | B1: Business Name | C1: Phone | D1: Has Website | E1: Website URL | F1: Website Quality | G1: Google Rating | H1: Review Count | I1: Flag | J1: Owner Name | K1: Notes | L1: Source | M1: Date Found
A2: Arlington | B2: Ronk Brothers Heating, Cooling, and Electrical | C2: (360) 325-4416 | D2: Yes | E2: ronkheating.com | F2: Professional | G2: 4.9 | H2: 948 | I2: Skip | K2: Large 50+ yr regional multi-location company (Skagit/Snohomish/Whatcom); modern branded site, runs paid Google ads | L2: Google Maps; WebSearch | M2: 2026-07-02
A3: Arlington | B3: Cozy Heating Inc. | C3: (360) 803-8914 | D3: Yes | E3: cozyheatinginc.com | F3: Professional | G3: 4.9 | H3: 405 | I3: Skip | J3: Vincent Lee Sr Willett (L&I principal) | K3: Family-owned since 1979; clean modern site, clear CTAs, financing page | L3: Google Maps; WebSearch | M3: 2026-07-02
A4: Arlington | B4: Northern Comfort Heating & Cooling | C4: (425) 588-4139 | D4: Yes | E4: northerncomfortpros.com | F4: Professional | G4: 4.9 | H4: 280 | I4: Skip | K4: Modern branded site, 24/7 messaging, clean navigation | L4: Google Maps; WebSearch | M4: 2026-07-02
A5: Arlington | B5: Barron Heating AC Electrical & Plumbing | C5: (360) 386-7990 | D5: Yes | E5: barronheating.com | F5: Professional | G5: 4.9 | H5: 195 | I5: Skip | K5: Large 50-yr regional multi-service company HQ'd in Bellingham; polished corporate site | L5: Google Maps; WebSearch | M5: 2026-07-02
A6: Arlington | B6: Custom Floor Heating LLC | C6: (206) 624-0889 | D6: Yes | E6: customfloorheating.com | F6: Not assessed | G6: 4.1 | H6: 14 | I6: Skip | K6: Below both rating and review thresholds | L6: Google Maps | M6: 2026-07-02
A7: Arlington | B7: Cascade Climate | C7: (425) 923-9089 | D7: Yes | F7: Not assessed | G7: 5 | H7: 1 | I7: Skip | K7: Only 1 review - insufficient data to qualify | L7: Google Maps | M7: 2026-07-02
A8: Arlington (Mount Vernon HQ) | B8: Janes Radiant Heating | C8: (800) 974-5884 | D8: Yes | E8: janescompany.com | F8: Professional | G8: 4.7 | H8: 394 | I8: Skip | K8: Large radiant-heat specialist covering Western WA; well outside core small-shop target profile | L8: Google Maps | M8: 2026-07-02
A9: Marysville | B9: Product Air Heating, Cooling, and Electric | C9: (425) 340-3591 | D9: Yes | E9: productairheating.com | F9: Professional | G9: 5 | H9: 802 | I9: Skip | K9: Large, fast-growing, women-owned; just opened a Seattle office. Strong reviews and marketing presence | L9: Google Maps | M9: 2026-07-02
A10: Marysville | B10: Dapper Plumbing, Heating, and Electrical | C10: (360) 358-5754 | D10: Yes | E10: dapperplumbing.com | F10: Professional | G10: 4.8 | H10: 626 | I10: Skip | K10: Large multi-service plumbing/HVAC/electrical company, polished branded site | L10: Google Maps; direct site visit | M10: 2026-07-02
A11: Marysville | B11: South West Plumbing, Heating, Air & Electric | C11: (360) 939-8504 | D11: Yes | F11: Professional (large chain) | G11: 5 | H11: 2007 | I11: Skip | K11: Large regional multi-service chain | L11: Google Maps | M11: 2026-07-02
A12: Marysville | B12: Paragon Heating and Home Comfort Solutions | C12: (360) 658-9500 | D12: Yes | E12: paragonheating.com | F12: Professional | G12: 4.8 | H12: 131 | I12: Skip | K12: Custom branded logo, real photography, polished design | L12: Google Maps; WebSearch; direct site visit | M12: 2026-07-02
A13: Marysville (Renton HQ) | B13: Energy Saver Solutions LLC | C13: (206) 558-8070 | D13: Yes | E13: energysaversolutionswa.com | F13: Not assessed | G13: 5 | H13: 167 | I13: Skip | K13: HQ'd in Renton/Seattle area, not a genuinely local Marysville shop | L13: Google Maps | M13: 2026-07-02
A14: Marysville | B14: Topline Marysville HVAC Repair | C14: (360) 654-7362 | D14: Yes | F14: Not assessed | G14: 5 | H14: 4 | I14: Skip | K14: Only 4 reviews - insufficient data to qualify | L14: Google Maps | M14: 2026-07-02
A15: Marysville | B15: Parker Bros Heating and Cooling | C15: (360) 572-0108 | D15: Yes | F15: Not assessed | G15: 4.7 | H15: 18 | I15: Skip | K15: Below 30-review threshold | L15: Google Maps | M15: 2026-07-02
A16: Marysville | B16: Nordstrom Heating & Air, Inc | C16: (360) 386-8770 | D16: Yes | F16: Not assessed | G16: 5 | H16: 5 | I16: Skip | K16: Below 30-review threshold | L16: Google Maps | M16: 2026-07-02
A17: Marysville | B17: Polk Mechanical, LLC | C17: (425) 268-1471 | D17: Yes | F17: Not assessed | G17: 5 | H17: 15 | I17: Skip | K17: Below 30-review threshold | L17: Google Maps | M17: 2026-07-02
A18: Marysville | B18: Elevated HVAC Technologies L.L.C. | C18: (425) 892-3623 | D18: Yes | F18: Not assessed | G18: 5 | H18: 12 | I18: Skip | K18: Below 30-review threshold | L18: Google Maps | M18: 2026-07-02
A19: Stanwood | B19: Stilly River Mechanical, Inc. | C19: (360) 387-3788 | D19: Yes | E19: stillyrivermechanical.com | F19: Professional | G19: 4.9 | H19: 574 | I19: Skip | K19: Modern branded site, clean lead form, 18+ year family-owned company | L19: Google Maps; WebSearch; direct site visit | M19: 2026-07-02
A20: Stanwood | B20: Lobach HeatCoolX Systems | C20: (425) 345-3095 | D20: Yes | F20: Not assessed | G20: 5 | H20: 13 | I20: Skip | K20: Below 30-review threshold | L20: Google Maps | M20: 2026-07-02
A21: Stanwood | B21: All-Ways Air Control | C21: (360) 939-2637 | D21: No | F21: N/A | G21: 3.2 | H21: 9 | I21: Skip | K21: Below both rating and review thresholds | L21: Google Maps | M21: 2026-07-02
A22: Stanwood | B22: Ronk Brothers Heating (Stanwood location) | C22: (360) 855-1025 | D22: Yes | E22: ronkheating.com | F22: Professional | G22: 0 | H22: 0 | I22: Skip | K22: No reviews yet at this location; part of the large Ronk Brothers group already flagged Skip in Arlington | L22: Google Maps | M22: 2026-07-02
A23: Stanwood (Whidbey/Fidalgo focus) | B23: Island Ductless Heat Pumps | C23: (360) 321-4252 | D23: Yes | E23: islandheatpumps.com | F23: Not assessed | G23: 4.9 | H23: 171 | I23: Skip | K23: Primarily serves Whidbey/Fidalgo Island communities, not a core Stanwood-area shop | L23: Google Maps; WebSearch | M23: 2026-07-02
A24: Stanwood | B24: Prince Mechanical | C24: (360) 965-9157 | D24: Yes | F24: Not assessed | G24: 5 | H24: 2 | I24: Skip | K24: Only 2 reviews - insufficient data | L24: Google Maps | M24: 2026-07-02
A25: Mount Vernon | B25: Foss Heating & Cooling | C25: (360) 336-1517 | D25: Yes | E25: fossheating.com | F25: Not deeply assessed (large, established) | G25: 4.9 | H25: 956 | I25: Skip | K25: Large, long-established Skagit County company with strong review volume; presumed professional web presence | L25: Google Maps | M25: 2026-07-02
A26: Mount Vernon | B26: CPI Plumbing & Heating | C26: (360) 447-6675 | D26: Yes | F26: Not deeply assessed (large) | G26: 4.8 | H26: 3080 | I26: Skip | K26: Very large multi-service plumbing/HVAC company | L26: Google Maps | M26: 2026-07-02
A27: Mount Vernon | B27: CM Heating | C27: (360) 535-7277 | D27: Yes | E27: cmheating.com | F27: Professional (large chain) | G27: 5 | H27: 1205 | I27: Skip | K27: Large Snohomish/Skagit multi-service HVAC/plumbing/electrical chain | L27: Google Maps | M27: 2026-07-02
A28: Mount Vernon | B28: Mount Vernon HVAC Pros | C28: (360) 382-4170 | D28: No | F28: N/A | G28: 5 | H28: 1 | I28: Skip | K28: Only 1 review - insufficient data to qualify | L28: Google Maps | M28: 2026-07-02
A29: Mount Vernon | B29: R & H Mechanical Inc | C29: (360) 757-6909 | D29: Yes | E29: rhmech.com | F29: Professional | G29: 4.4 | H29: 51 | I29: Skip | K29: Clean modern site, real photography, since 1976 | L29: Google Maps; WebSearch; direct site visit | M29: 2026-07-02
A30: Mount Vernon | B30: SUNDANCE Energy | C30: (360) 295-9300 | D30: Yes | F30: Not assessed | G30: 4.2 | H30: 17 | I30: Skip | K30: Below 30-review threshold | L30: Google Maps | M30: 2026-07-02
A31: Mount Vernon | B31: All Phase Heating and Air Conditioning Inc. | C31: (360) 707-8521 | D31: Yes | F31: Not assessed | G31: 4.5 | H31: 16 | I31: Skip | K31: Below 30-review threshold | L31: Google Maps | M31: 2026-07-02
A32: Everett | B32: Home Comfort Alliance - Everett | C32: (425) 250-8005 | D32: Yes | E32: homecomfortalliance.com | F32: Professional (large chain) | G32: 4.8 | H32: 1776 | I32: Skip | K32: Large multi-city company running paid Google Ads | L32: Google Maps | M32: 2026-07-02
A33: Everett | B33: Greenwood Heating and Home Services | C33: (206) 207-4734 | D33: Yes | E33: greenwoodheating.com | F33: Not deeply assessed (large, established) | G33: 4.7 | H33: 210 | I33: Skip | K33: Full-service HVAC/electrical/plumbing company serving Everett since 1921 | L33: Google Maps; WebSearch | M33: 2026-07-02
A34: Everett | B34: North Heat & Air | C34: (425) 550-2203 | D34: Yes | E34: northheatair.com | F34: Professional | G34: 4.9 | H34: 39 | I34: Skip | K34: Modern branded site with real truck/team photography | L34: Google Maps; WebSearch; direct site visit | M34: 2026-07-02
A35: Everett | B35: Holy Moly Electric Plumbing Heating Air | C35: (425) 908-0030 | D35: Yes | F35: Not deeply assessed (large multi-service) | G35: 4.7 | H35: 328 | I35: Skip | K35: Large multi-service electric/plumbing/HVAC operator | L35: Google Maps | M35: 2026-07-02
A36: Everett | B36: Sound Comfort Heating and Air Conditioning | C36: (425) 225-4756 | D36: Yes | E36: soundcomfortheating.com | F36: Professional | G36: 5 | H36: 171 | I36: Skip | K36: Clean modern site with lead form and financing messaging | L36: Google Maps; WebSearch; direct site visit | M36: 2026-07-02
A37: Everett | B37: Eco Electric, Plumbing, Heating and Air | C37: (206) 800-6975 | D37: Yes | F37: Not deeply assessed (large multi-service) | G37: 4.9 | H37: 309 | I37: Skip | K37: Large multi-service electric/plumbing/HVAC operator | L37: Google Maps | M37: 2026-07-02
A38: Everett | B38: Northwest Thermal Solutions | C38: (425) 530-9488 | D38: Yes | F38: Not assessed | G38: 5 | H38: 4 | I38: Skip | K38: Only 4 reviews - insufficient data | L38: Google Maps | M38: 2026-07-02
A39: Everett | B39: Better Air NW Heating & Cooling | C39: (206) 898-5743 | D39: Yes | E39: betterairnw.com | F39: Not deeply assessed (large, established) | G39: 4.9 | H39: 412 | I39: Skip | K39: Woman-run company since 2009, strong review volume and marketing presence | L39: Google Maps; WebSearch | M39: 2026-07-02
A40: Everett | B40: Washington Energy Services | C40: (800) 398-4663 | D40: Yes | E40: washingtonenergy.com | F40: Not deeply assessed (very large) | G40: 4.7 | H40: 911 | I40: Skip | K40: Very large regional home-services company running paid Google Ads | L40: Google Maps | M40: 2026-07-02
...

Sheet L&I Goldmine
A1: Business Name | B1: City | C1: Phone | D1: License Since | E1: Years Licensed | F1: Already in Sheet? | G1: Triage Result | H1: Notes | I1: Geo Tier
A2: L & K Heating | B2: Nine Mile Falls | C2: 5097685601 | D2: 1981-03-19 | E2: 45.3 | G2: Hot - logged | I2: 1
A3: Todd Sheet Metal | B3: Suquamish | C3: 3605984517 | D3: 1981-07-01 | E3: 45 | G3: Hot - logged | I3: 1
A4: Action Heating/Air Condtng | B4: Carnation | C4: 4254511464 | D4: 1983-07-15 | E4: 43 | G4: Watch - logged | I4: 1
A5: Comfort Mechanical Contrs Inc | B5: Greenacres | C5: 5099280207 | D5: 1997-05-07 | E5: 29.2 | G5: Watch - logged | I5: 1
A6: Naylors Appliance & Refrigertn | B6: Tonasket | C6: 5094862351 | D6: 1997-08-22 | E6: 28.9 | G6: Hot - logged | I6: 1
A7: Dr Cool Inc | B7: Sumner | C7: 2538635665 | D7: 1998-11-05 | E7: 27.7 | G7: Skip - logged | I7: 1
A8: Action Plumbing & Htg Inc | B8: Dryden | C8: 5095484458 | D8: 2000-02-28 | E8: 26.3 | G8: Watch - logged | I8: 1
A9: Carlson'S Heating & A/C Inc | B9: Kelso | C9: 3604254888 | D9: 2000-02-28 | E9: 26.3 | G9: Skip - logged | I9: 1
A10: Mantey Heating | B10: Moxee | C10: 5099665520 | D10: 2000-02-28 | E10: 26.3 | G10: Skip - logged (closed) | I10: 1
A11: Accent Heating & Cooling Llc | B11: Brush Prairie | C11: 3608851940 | D11: 2000-03-01 | E11: 26.3 | G11: Warm - logged | I11: 1
A12: Morris Plumbing & Heating | B12: Eastsound | C12: 3603176104 | D12: 2000-03-01 | E12: 26.3 | G12: Hot - logged | I12: 1
A13: Action Heating & Air Cond | B13: Carnation | C13: 4254511464 | D13: 2000-03-02 | E13: 26.3 | G13: Watch - logged | I13: 1
A14: Twin City Srvc Co Inc | B14: Kelso | C14: 3604253320 | D14: 2000-04-24 | E14: 26.2 | G14: Warm - logged | H14: PASF intel 2026-07-02: GMB "Twin City Service Co" 4.9/74 - meets bar, check website when triaged | I14: 1
A15: Sea Aire Inc | B15: Algona | C15: 2065758051 | D15: 2000-05-12 | E15: 26.1 | G15: Skip - logged | I15: 1
A16: Naylor'S Appliance/Refrig Inc | B16: Tonasket | C16: 5094862351 | D16: 2000-05-15 | E16: 26.1 | G16: Hot - logged | I16: 1
A17: Comfort Air Systems | B17: Orting | C17: 2532274670 | D17: 2000-06-28 | E17: 26 | G17: Skip - logged | I17: 1
A18: Orca Heating & A/C | B18: Quil Ceda Village | C18: 4253599208 | D18: 2001-03-08 | E18: 25.3 | G18: RE-CHECK - phone mismatch vs GMB | H18: L&I ph 4253599208 != Tulalip GMB 4255082484; skipped GMB may be different company. Call L&I number. | I18: 1
A19: Freels Refrigeration | B19: Omak | C19: 5098265492 | D19: 2001-03-21 | E19: 25.3 | G19: Hot - logged | I19: 1
A20: Terry'S Appliance Service | B20: Winthrop | C20: 5099963741 | D20: 2001-06-29 | E20: 25 | G20: Skip - logged | I20: 1
A21: Olympic Heating & Cooling Llc | B21: Shelton | C21: 3604269945 | D21: 2001-12-31 | E21: 24.5 | G21: Skip - logged | I21: 1
A22: D K Systems Inc | B22: Burlington | C22: 3607551555 | D22: 2002-07-26 | E22: 23.9 | G22: Watch - logged | I22: 1
A23: Compass Mechanical Llc | B23: Coulee City | C23: 5097592321 | D23: 2002-08-02 | E23: 23.9 | G23: Hot - logged | I23: 1
A24: T & M Heating & Refrig Inc | B24: Union Gap | C24: 5095751088 | D24: 2002-08-19 | E24: 23.9 | G24: Hot - logged | I24: 1
A25: Tradesman'S Mechanical Service | B25: Oakville | C25: 3602809270 | D25: 2002-12-19 | E25: 23.5 | G25: Hot - logged | I25: 1
A26: Thermal Air Llc | B26: Oroville | C26: 5094763145 | D26: 2003-04-02 | E26: 23.2 | G26: Hot - logged | I26: 1
A27: Allencraft Enterprise | B27: Morton | C27: 3604963244 | D27: 2003-05-06 | E27: 23.2 | G27: Skip - logged | I27: 1
A28: Central Energy Products Llc | B28: Ephrata | C28: 5097602882 | D28: 2003-08-19 | E28: 22.9 | G28: Hot - logged | I28: 1
A29: Refresh Llc | B29: North Bend | C29: 4254503222 | D29: 2003-12-18 | E29: 22.5 | G29: Hot - logged | I29: 1
A30: Lopez Heating Systems | B30: Lopez Island | C30: 3604682574 | D30: 2004-02-05 | E30: 22.4 | G30: Hot - logged | I30: 1
A31: Gfr Heating & Cooling Llc | B31: Milton | C31: 2062443996 | D31: 2005-02-14 | E31: 21.4 | G31: Watch - logged | I31: 1
A32: R & H Mechanical Inc | B32: Burlington | C32: 3607576909 | D32: 2005-06-03 | E32: 21.1 | F32: Yes | I32: 1
A33: All Weather Htg A/C & Rfrg Llc | B33: Snoqualmie | C33: 4254639814 | D33: 2006-01-04 | E33: 20.5 | G33: Skip - logged | I33: 1
A34: All Weather Htg A/C/Refrig Llc | B34: Snoqualmie | C34: 4254639814 | D34: 2006-01-04 | E34: 20.5 | G34: Skip - logged (dup row) | I34: 1
A35: Americool Heating And A/C Llc | B35: Rochester | C35: 3602733300 | D35: 2006-01-27 | E35: 20.4 | G35: Skip - logged | I35: 1
A36: Dunsmore Heating & Gas Piping | B36: Clinton | C36: 3602218567 | D36: 2006-02-28 | E36: 20.3 | G36: Hot - logged | I36: 1
A37: Heating Guy Inc | B37: Deming | C37: 3609274643 | D37: 2006-03-24 | E37: 20.3 | F37: Yes | I37: 1
A38: North Cascades Htg & A/C Inc | B38: Entiat | C38: 5097844822 | D38: 2006-04-11 | E38: 20.2 | G38: Skip - logged | I38: 1
A39: Freedom Heating And Ac Llc | B39: Mccleary | C39: 3604702888 | D39: 2006-06-15 | E39: 20 | G39: Hot - logged | I39: 1
A40: Kimball Mechanical | B40: Snoqualmie | C40: 4258644745 | D40: 2006-07-21 | E40: 19.9 | G40: Hot - logged | I40: 1
...
